Workbook

Sheet 0_Hướng dẫn
A1: CS9 · Kinh tế sản phẩm AI: chi phí, định giá, hiệu quả đầu tư — File thực hành
A2: AI in Action · Track 1 · Khóa 4. FILE LÀM BÀI CỦA NHÓM. Nhóm chưa có dự án chung: chọn 1 trong 3 đề bài giả định (file CS9_DeBai_GiaDinh.pdf). Ví dụ cách điền: bản mẫu "trợ lý AI trả lời tin nhắn Zalo cho cửa hàng nhỏ" ở cột Gợi ý (trang 1, 3, 6), bảng cách nhập ở trang 2, và trong file CS9_HuongDan_HocVien.pdf.
A3: Ô tự kiểm tra: "Đạt" là ổn. "Xem lại", "Chưa đủ sốc" là câu hỏi để nhóm soát: sửa nếu nhập sai; nếu số đúng thì giữ nguyên và giải thích ở trang 7. Không chỉnh giả định chỉ để được "Đạt".
A4: Luật chơi: CHỈ điền vào ô màu VÀNG (một số ô vàng có sẵn số mặc định, sửa được). Ô màu XANH LÁ NHẠT là công thức, đã khóa. Cột "Gợi ý" chữ xám (trang 1, 3, 6) chỉ cách lấy số và giá trị của bản mẫu, không cần điền.
A5: Thứ tự và thời gian: Nhiệm vụ 0 · trang 0 (5 phút) → Phần A · trang A: Bài 1 (10 phút), rồi Bài 2, Bài 3 và câu 1–3 (14 phút) → Nhiệm vụ 1 · trang 1 (15 phút) → Nhiệm vụ 2 · trang 2 (15 phút) → Nhiệm vụ 3 · trang 3, 4, 5 (26 phút) → Nhiệm vụ 4 · trang 6 (chỉ khi sản phẩm phục vụ chính công ty) và trang 7 (23 phút), rồi nộp file. Hết giờ mà chưa xong: để nguyên, sang việc kế tiếp, cuối giờ quay lại.
A6: Mỗi con số phải có NGUỒN hoặc LÝ DO ở cột "Nguồn / lý do". Gắn nhãn như Ngày 23: [NGÀNH] số chuẩn ngành, có đường dẫn · [TỰ TÍNH] tính từ mô hình · [TỰ ĐO] nhóm tự đo. Số chưa có nguồn, chưa đo: ghi "Giả định: … vì … · sẽ đo bằng …". Không gắn [NGÀNH] khi không chỉ ra được nguồn. Không nguồn, không lý do = bị trừ điểm.
A7: Giá token: tra bảng giá chính thức của nhà cung cấp vào ngày làm bài, ghi tên mô hình và ngày tra. Tỷ giá: ghi nguồn và ngày. Trang 9 có sẵn một số số liệu đã kiểm chứng.
A8: Kịch bản xấu phải là cú sốc thật: tỷ lệ rời bỏ và chi phí có một khách tối thiểu gấp 1,5 lần kịch bản cơ sở (trang 3 tự kiểm tra).
A9: Ngưỡng tham khảo (không phải luật): giá mỗi việc ≥ 3 × chi phí mỗi việc · biên lợi nhuận gộp bình quân ≥ 60% · LTV ÷ CAC > 3 · hoàn vốn chi phí có khách < 12 tháng · kịch bản xấu còn tiền ≥ 12 tháng hoặc có kế hoạch cắt giảm. Mốc 50% ở trang 2 là cách đọc của Ngày 23 cho biên SAU KHI CHIA cho đối tác. Khi ra quyết định, ưu tiên mức tự tính ở trang 5, dòng 72–77.
A10: Tên file nộp: [Nhom]_CS9.xlsx · Nộp lên VLearn khi hết Nhiệm vụ 4.
A11: Nối hai buổi trước: mang phiếu bài tập 1 và bài về nhà một trang của Ngày 22 (định giá, kênh bán), và bảng theo dõi chỉ số của Ngày 23. Trang 0 chỉ chỗ dùng từng thứ.
A12: Nguồn tham khảo khung bài: AI in Action khóa 3 — Ngày 24 Mô hình tài chính (slide và sổ tay), Ngày 25 Định giá và đưa sản phẩm ra thị trường (Đàm Bá Quyền). File này được dựng lại cho khóa 4.
... A18: Chữ xám nghiêng ở cột Gợi ý: cách lấy số và giá trị bản mẫu (không cần điền)

Sheet 0_Đầu vào
A1: 0 · Nhiệm vụ 0: gom đầu vào — có thì tận dụng, chưa có thì làm mới (5 phút)
A2: Đánh dấu nhóm đã có hay chưa. Cả hai lối đi đều đủ điểm. Dùng số thật từ buổi trước được cộng tối đa 10 điểm.
A4: Có thể đã có từ buổi trước | B4: Nhóm đã có chưa? | C4: Nếu ĐÃ CÓ: dùng ở đâu | D4: Nếu CHƯA CÓ: làm gì | E4: Ghi chú (tên file, đường dẫn)
A5: Mô hình hiệu quả đầu tư 3–6–12 tháng và tài liệu yêu cầu sản phẩm (Phase 1, Ngày 6) | C5: Làm phiên bản 2; so sánh con số cũ và mới ở trang 3–5 | D5: Dựng mới trên file này
A6: Bảng giám sát agent: token, chi phí theo ngày (Ngày 13) | C6: Lấy số lần gọi AI và token thật ở trang 1 | D6: Chạy thử 5 câu hỏi, xem số token ở trang quản lý API (cách làm: trang 1, cột Gợi ý)
A7: Báo cáo đánh giá chất lượng (Ngày 14 hoặc buổi đánh giá Track 1) | C7: Tỷ lệ chưa đạt → tỷ lệ cần người kiểm tra ở trang 1 | D7: Giả định 10–20%, ghi lý do
A8: Phiếu bài tập 1 và bài về nhà một trang (Ngày 22) | C8: Cách tính tiền, chi phí mỗi việc, giá đề xuất: chép vào trang 1–2 rồi soát lại | D8: Làm nhanh ở Nhiệm vụ 1–2 theo bản mẫu (cột Gợi ý ở trang 1–2)
A9: Bảng theo dõi chỉ số và luật xử lý (Ngày 23) | C9: Điền mức cảnh báo tự tính (trang 5, dòng 72–77) vào cột [TỰ TÍNH] | D9: Dùng bảng mức cảnh báo ở trang 5 làm khung
A10: Sản phẩm của nhóm từ các buổi trước | C10: Dùng xuyên suốt | D10: Nhóm ngồi chung bàn nhưng khác dự án: chọn 1 trong 3 đề bài giả định trong file CS9_DeBai_GiaDinh.pdf (đề cho sẵn số liệu trang 1–3; ghi tên đề ở cột Ghi chú)
A12: Số đầu vào nhóm đã có | B12: =COUNTIF(B5:B10,"Có") -> 0
A13: Điểm thưởng gợi ý (tối đa 10): 2 điểm cho mỗi đầu vào đã có và thật sự được dùng trong bài

Sheet A_Tài chính căn bản
A1: A · Bài tập tài chính doanh nghiệp căn bản: lập ba báo cáo tài chính
A2: Công ty Trợ Lý Xanh bán trợ lý AI trả lời tin nhắn. Dưới đây là mọi giao dịch của 3 tháng đầu. Lập báo cáo kết quả kinh doanh, bảng cân đối kế toán và báo cáo lưu chuyển tiền tệ.
A3: Đơn vị: triệu đồng. Điền ô VÀNG, kể cả các dòng lợi nhuận và dòng tổng (gõ số hoặc công thức như =SUM). Ô tự kiểm tra (cột G) chỉ báo cộng trừ đúng và ba báo cáo khớp nhau; "Đạt" chưa chắc đã ghi đúng kỳ. Dòng 33 kiểm tra riêng việc ghi theo kỳ.
A5: ĐỀ BÀI · Giao dịch 3 tháng đầu
A6: STT | B6: Giao dịch | C6: Tháng 1 | D6: Tháng 2 | E6: Tháng 3 | F6: Ghi chú | G6: Bài 1 · Vào báo cáo kết quả? (Có / Không · vì sao)
A7: 1 | B7: Chủ sở hữu góp vốn bằng tiền | C7: 1000 | G7: Có. Vốn
A8: 2 | B8: Vay ngân hàng, gốc trả sau 3 năm | C8: 300 | F8: Lãi 12%/năm, trả cuối mỗi tháng | G8: Lãi vay
A9: 3 | B9: Mua máy chủ, trả tiền ngay | C9: 360 | F9: Dùng 36 tháng, khấu hao đều | G9: Có. Chi phí
A10: 4 | B10: Bán gói tháng cho cửa hàng nhỏ, thu tiền ngay | C10: 50 | D10: 80 | E10: 110 | G10: Có. Doanh thu lấy ngay
A11: 5 | B11: Ngân hàng X trả trước gói 12 tháng | C11: 240 | F11: Dịch vụ chạy đều từ tháng 1 | G11: Có. Doanh thu tháng
A12: 6 | B12: Dự án triển khai cho công ty Y được nghiệm thu | D12: 90 | F12: Y trả tiền sau 60 ngày (tháng 4) | G12: Có. Doanh thu
A13: 7 | B13: Chi phí gọi AI phát sinh trong tháng | C13: 15 | D13: 25 | E13: 35 | F13: Nhà cung cấp cho trả vào tháng sau | G13: Có. Chi phí mỗi tháng
A14: 8 | B14: Người kiểm tra câu trả lời, trả trong tháng | C14: 10 | D14: 10 | E14: 10 | G14: Có. Chi phí đều mỗi tháng
A15: 9 | B15: Lương đội phát triển và bán hàng, trả trong tháng | C15: 120 | D15: 120 | E15: 120 | G15: Có. Chi phí đều mỗi tháng
A16: 10 | B16: Thuê văn phòng, trả trong tháng | C16: 20 | D16: 20 | E16: 20 | G16: Có. Chi phí đều mỗi tháng
A17: 11 | B17: Thuế thu nhập doanh nghiệp | C17: 0 | D17: 0 | E17: 0 | F17: Lỗ lũy kế nên chưa phát sinh thuế | G17: Có. Thuế
A19: BÀI 1 · BÁO CÁO KẾT QUẢ KINH DOANH (10 phút). Ghi theo tháng phát sinh, không theo ngày tiền vào ra. Chi phí ghi số dương; dòng lợi nhuận = kết quả cộng trừ.
B20: Khoản mục | C20: Tháng 1 | D20: Tháng 2 | E20: Tháng 3 | F20: Cộng 3 tháng | G20: Tự kiểm tra
B21: Doanh thu | C21: =C10+C11/12+C12 -> 70 | D21: =D10+C11/12+D12 -> 190 | E21: =E10+C11/12+E12 -> 130 | F21: =IF(COUNT(C21:E21)=0,"",SUM(C21:E21)) -> 390
B22: Giá vốn (gọi AI + người kiểm tra) | C22: =C13+C14 -> 25 | D22: =D13+D14 -> 35 | E22: =E13+E14 -> 45 | F22: =IF(COUNT(C22:E22)=0,"",SUM(C22:E22)) -> 105
B23: Lợi nhuận gộp | C23: =C21-C22 -> 45 | D23: =D21-D22 -> 155 | E23: =E21-E22 -> 85 | F23: =IF(COUNT(C23:E23)=0,"",SUM(C23:E23)) -> 285 | G23: =IF(COUNT(C21:E21,C22:E22,C23:E23)<9,"Chưa điền",IF(AND(ABS(C23-(C21-C22))<0.01,ABS(D23-(D21-D22))<0.01,ABS(E23-(E21-E22))<0.01),"Đạt","Xem lại phép trừ")) -> Đạt
B24: Chi phí hoạt động (lương + văn phòng) | C24: =SUM(C15:C17) -> 140 | D24: =SUM(D15:D17) -> 140 | E24: =SUM(E15:E17) -> 140 | F24: =IF(COUNT(C24:E24)=0,"",SUM(C24:E24)) -> 420
B25: Lợi nhuận trước lãi vay, thuế và khấu hao (EBITDA) | C25: =C23-C24 -> -95 | D25: =D23-D24 -> 15 | E25: =E23-E24 -> -55 | F25: =IF(COUNT(C25:E25)=0,"",SUM(C25:E25)) -> -135 | G25: =IF(COUNT(C23:E23,C24:E24,C25:E25)<9,"Chưa điền",IF(AND(ABS(C25-(C23-C24))<0.01,ABS(D25-(D23-D24))<0.01,ABS(E25-(E23-E24))<0.01),"Đạt","Xem lại phép trừ")) -> Đạt
B26: Khấu hao | C26: =C9/36 -> 10 | D26: =C9/36 -> 10 | E26: =C9/36 -> 10 | F26: =IF(COUNT(C26:E26)=0,"",SUM(C26:E26)) -> 30
B27: Lợi nhuận hoạt động | C27: =C25-C26 -> -105 | D27: =D25-D26 -> 5 | E27: =E25-E26 -> -65 | F27: =IF(COUNT(C27:E27)=0,"",SUM(C27:E27)) -> -165 | G27: =IF(COUNT(C25:E25,C26:E26,C27:E27)<9,"Chưa điền",IF(AND(ABS(C27-(C25-C26))<0.01,ABS(D27-(D25-D26))<0.01,ABS(E27-(E25-E26))<0.01),"Đạt","Xem lại phép trừ")) -> Đạt
B28: Lãi vay | C28: =C8*0.12/12 -> 3 | D28: =C8*0.12/12 -> 3 | E28: =C8*0.12/12 -> 3 | F28: =IF(COUNT(C28:E28)=0,"",SUM(C28:E28)) -> 9
B29: Lợi nhuận trước thuế | C29: =C27-C28 -> -108 | D29: =D27-D28 -> 2 | E29: =E27-E28 -> -68 | F29: =IF(COUNT(C29:E29)=0,"",SUM(C29:E29)) -> -174 | G29: =IF(COUNT(C27:E27,C28:E28,C29:E29)<9,"Chưa điền",IF(AND(ABS(C29-(C27-C28))<0.01,ABS(D29-(D27-D28))<0.01,ABS(E29-(E27-E28))<0.01),"Đạt","Xem lại phép trừ")) -> Đạt
B30: Thuế thu nhập doanh nghiệp | C30: =C17 -> 0 | D30: =D17 -> 0 | E30: =E17 -> 0 | F30: =IF(COUNT(C30:E30)=0,"",SUM(C30:E30)) -> 0
B31: Lợi nhuận sau thuế | C31: =C29-C30 -> -108 | D31: =D29-D30 -> 2 | E31: =E29-E30 -> -68 | F31: =IF(COUNT(C31:E31)=0,"",SUM(C31:E31)) -> -174 | G31: =IF(COUNT(C29:E29,C30:E30,C31:E31)<9,"Chưa điền",IF(AND(ABS(C31-(C29-C30))<0.01,ABS(D31-(D29-D30))<0.01,ABS(E31-(E29-E30))<0.01),"Đạt","Xem lại phép trừ")) -> Đạt
B32: Biên lợi nhuận gộp | C32: =IFERROR(C23/C21,"") -> 0.64285714 | D32: =IFERROR(D23/D21,"") -> 0.81578947 | E32: =IFERROR(E23/E21,"") -> 0.65384615 | F32: =IFERROR(F23/F21,"") -> 0.73076923
B33: KIỂM TRA ghi theo kỳ: tổng lợi nhuận sau thuế 3 tháng (ô F31) có bằng −174 (số ở câu 3) không? | G33: =IF(COUNT(C31:E31)<3,"Chưa điền",IF(ABS(F31+174)<0.01,"Đạt: đã ghi theo kỳ","Chưa đúng: có giao dịch đang ghi theo ngày tiền vào ra (xem cột G, dòng 7–17)")) -> Đạt: đã ghi theo kỳ
A34: BÀI 2 · BẢNG CÂN ĐỐI KẾ TOÁN cuối tháng 3 (Bài 2 và 3: 14 phút). Hao mòn lũy kế ghi số âm; lợi nhuận giữ lại đang lỗ thì ghi số âm.
B35: Khoản mục | C35: Số tiền | G35: Tự kiểm tra
B36: TÀI SẢN
B37: Tiền
B38: Phải thu khách hàng
B39: Máy chủ — nguyên giá
B40: Hao mòn lũy kế
B41: Tổng tài sản | G41: =IF(COUNT(C37:C41)<5,"Chưa điền",IF(ABS(C41-SUM(C37:C40))<0.01,"Đạt","Xem lại phép cộng")) -> Chưa điền
B42: NỢ PHẢI TRẢ
...

Sheet 1_Chi phí mỗi việc
A1: 1 · Chi phí để AI làm xong 1 việc
A2: 'Việc' = 1 đơn vị công việc khách nhận được, ví dụ: 1 hội thoại được trả lời, 1 hồ sơ được đọc, 1 cuộc gọi.
A3: Chỉ tính chi phí phục vụ từng việc (giá vốn). KHÔNG tính lương đội phát triển (→ chi phí cố định), chi phí thử sai trước khi ra mắt (→ chi phí xây dựng ban đầu) và quảng cáo, bán hàng (→ chi phí có một khách); cả ba ở trang 3, nếu không sẽ bị trừ hai lần.
A4: Hạng mục | B4: Giá trị | C4: Đơn vị | D4: Nguồn / lý do | E4: Gợi ý cách lấy số · bản mẫu
A5: Mô tả 1 việc (Ngày 22 gọi là job) | B5: 1 mô tả sản phẩm hoặc 1 câu trả lời đánh giá | D5: Đề bài 3 | E5: Một câu: AI nhận gì, trả ra gì cho khách. Bản mẫu: trả lời 1 hội thoại Zalo của khách cho cửa hàng nhỏ.
A6: Số lần gọi mô hình / việc | B6: 1 | C6: lần | D6: Đề bài 3 | E6: Đếm số bước phải gọi mô hình cho 1 việc: hiểu câu hỏi, tra cứu, soạn trả lời, tự kiểm tra. Bản mẫu: 2.
A7: Token đầu vào / lần gọi | B7: 1200 | C7: token | D7: Đề bài 3 (thông tin SP & giọng văn) | E7: Gồm câu lệnh hệ thống + tài liệu tra cứu + lịch sử hội thoại + câu hỏi. Có bảng giám sát agent thì lấy số thật; chưa có thì chạy thử 5 câu và xem số token ở trang quản lý API. Bản mẫu: 2.000.
A8: Token đầu ra / lần gọi | B8: 400 | C8: token | D8: Đề bài 3 | E8: Độ dài câu trả lời, đếm bằng cách chạy thử. Bản mẫu: 300 (1–3 câu ngắn).
A9: Giá token đầu vào | B9: 0.1 | C9: USD / 1 triệu token | D9: GPT-6 Luna (trang 9) | E9: Chọn 1 mô hình ở trang 9 hoặc trang giá chính thức. Ghi tên mô hình, ngày tra, đường dẫn ở cột D. Bản mẫu: 0,4 USD (mô hình nhỏ giả định; nhóm thay bằng giá mô hình thật).
A10: Giá token đầu ra | B10: 0.5 | C10: USD / 1 triệu token | D10: GPT-6 Luna (trang 9) | E10: Như dòng 9. Giá đầu ra thường cao hơn đầu vào nhiều lần. Bản mẫu: 1,6 USD.
A11: Tỷ giá | B11: 26170 | C11: VND / USD | D11: Tỷ giá trang 9 | E11: Tỷ giá bán ra Vietcombank ở trang 9 (26.170 đồng, ngày 04/10/2026) hoặc tra mới, ghi ngày. Bản mẫu: 26.000.
A12: Tỷ lệ gọi lại khi lỗi | B12: 0.05 | C12: % | D12: Đề bài 3 | E12: Tỷ lệ việc phải gọi lại vì lỗi, hết thời gian chờ, trả lời hỏng. Chưa đo: giả định 5–10%, ghi lý do. Bản mẫu: 10%.
A13: Hạ tầng / việc (máy chủ, cơ sở dữ liệu, gửi tin) | B13: 20 | C13: VND | D13: Đề bài 3 | E13: Hoá đơn hạ tầng tăng theo lượt dùng (máy chủ, cơ sở dữ liệu, gửi tin) mỗi tháng ÷ số việc mỗi tháng. Phần trả cố định hằng tháng để ở trang 3, dòng 11. Bản mẫu: 100 đồng.
A14: Tỷ lệ việc cần người kiểm tra | B14: 0.02 | C14: % | D14: Đề bài 3 (chỉ khi khách báo lỗi) | E14: Lấy từ báo cáo đánh giá chất lượng (tỷ lệ trả lời chưa đạt). Chưa có: giả định 10–20%. Bản mẫu: 10%.
A15: Số phút người kiểm tra / việc | B15: 1 | C15: phút | D15: Đề bài 3 | E15: Thời gian 1 người đọc và sửa 1 kết quả. Bản mẫu: 1,5 phút.
A16: Chi phí nhân sự kiểm tra | B16: 40000 | C16: VND / giờ | D16: Đề bài 3 | E16: Bằng (lương tháng + bảo hiểm) ÷ số giờ làm mỗi tháng (khoảng 176–208 giờ). Lương tối thiểu ở trang 9 chỉ là mức sàn. Bản mẫu: 60.000 đồng/giờ.
A17: Đánh giá chất lượng, giám sát, gán nhãn lại / việc | B17: 5 | C17: VND | D17: Đề bài 3 | E17: Chi phí chạy bộ câu hỏi đánh giá, gán nhãn lại mỗi tháng ÷ số việc mỗi tháng. Bản mẫu: 60 đồng.
A18: Chi phí khác / việc (tuân thủ, lưu nhật ký…) | B18: 5 | C18: VND | D18: Đề bài 3 | E18: Lưu nhật ký, bảo mật, tuân thủ. Ghi 0 thì nói vì sao. Bản mẫu: 30 đồng.
A20: KẾT QUẢ
A21: Chi phí gọi AI / việc (đã tính gọi lại) | B21: =IFERROR(B6*(B7*B9+B8*B10)/1000000*B11*(1+B12),0) -> 8.79312
A22: Chi phí người kiểm tra / việc | B22: =IFERROR(B14*B15/60*B16,0) -> 13.333333
A23: Hạ tầng + đánh giá + khác / việc | B23: =B13+B17+B18 -> 30
A24: TỔNG CHI PHÍ MỖI VIỆC | B24: =B21+B22+B23 -> 52.126453 | E24: Bản mẫu: khoảng 413 đồng mỗi việc, trong đó gọi AI chỉ khoảng 73 đồng.
A25: Phần chìm so với chi phí gọi AI | B25: =IFERROR((B24-B21)/B21,0) -> 4.9280953 | C25: Dưới 30%: rà lại xem đã đủ các khoản chưa (kinh nghiệm giảng viên). Không thêm khoản bịa chỉ để đạt mốc.
A26: Giá sàn mỗi việc = 3 × chi phí mỗi việc | B26: =3*B24 -> 156.37936 | C26: Dùng cho giá từng việc, kể cả giá vượt hạn mức (biên ≈ 67%): chừa đệm cho khách dùng nhiều và giá AI biến động
A27: Giá tối thiểu để biên lợi nhuận gộp đạt 60% | B27: =B24/(1-0.6) -> 130.31613 | C27: Giá bình quân mỗi việc của cả tệp khách nên cao hơn số này (để biên bình quân ≥ 60%, trang 4 và 7). Giá từng việc, kể cả phí vượt, dùng dòng 26.

Sheet 2_Định giá
A1: 2 · Định giá: cách tính tiền, gói giá và nhóm khách dùng nhiều
A2: So sánh gói kết hợp (phí cố định + phí vượt hạn mức) với gói không giới hạn để thấy rủi ro từ nhóm khách dùng nhiều.
A4: Mục | B4: Giá trị | C4: Ghi chú | D4: Nguồn / lý do
A5: Khách trả tiền từ ngân sách nào? | B5: Phần mềm (người bán tự trả, ngân sách nhỏ) | C5: Phần mềm hay Nhân sự? | D5: Đề bài 3
A6: Cách tính tiền đã chọn | B6: Kết hợp (phí cố định + vượt hạn mức) | C6: Bảng giá dưới luôn có dạng phí cố định + phí mỗi việc vượt hạn mức. Cách nhập cho từng cách tính tiền: dòng 35–40. | D6: Đề bài 3
A7: Lý do chọn (hai câu hỏi: đo được kết quả? AI tự làm trọn?)
A8: Neo giá so với cái gì? | B8: Lương cộng tác viên viết nội dung bán thời gian | C8: Lương hoặc chi phí thuê ngoài, không so với giá ChatGPT | D8: Đề bài 3
A9: Phí cố định / khách / tháng | B9: 99000 | C9: VND | D9: Đề bài 3
A10: Số việc đã gồm trong phí cố định | B10: 300 | C10: việc / tháng | D10: Đề bài 3
A11: Giá mỗi việc vượt hạn mức | B11: 300 | C11: VND / việc | D11: Đề bài 3
A12: Giá gói không giới hạn (để so sánh; thường = phí cố định dòng 9) | B12: 99000 | C12: VND / tháng | D12: Đề bài 3
A14: Nhóm khách | B14: Tỷ trọng số khách (2 dòng cộng = 100%) | C14: Số việc / 1 khách / tháng | D14: Doanh thu / khách (gói kết hợp) | E14: Chi phí AI / khách (= số việc × chi phí mỗi việc) | F14: Biên lợi nhuận gộp (kết hợp) | G14: Doanh thu / khách (không giới hạn) | H14: Biên lợi nhuận gộp (không giới hạn) | I14: Nguồn / lý do
A15: Khách thường | B15: 0.85 | C15: 120 | D15: =B9+MAX(0,C15-B10)*B11 -> 99000 | E15: =C15*'1_Chi phí mỗi việc'!B24 -> 6255.1744 | F15: =IFERROR((D15-E15)/D15,0) -> 0.93681642 | G15: =B12 -> 99000 | H15: =IFERROR((G15-E15)/G15,0) -> 0.93681642 | I15: Đề bài 3
A16: Khách dùng nhiều | B16: 0.15 | C16: 1200 | D16: =B9+MAX(0,C16-B10)*B11 -> 369000 | E16: =C16*'1_Chi phí mỗi việc'!B24 -> 62551.744 | F16: =IFERROR((D16-E16)/D16,0) -> 0.83048308 | G16: =B12 -> 99000 | H16: =IFERROR((G16-E16)/G16,0) -> 0.3681642 | I16: Đề bài 3
A17: BÌNH QUÂN (theo tỷ trọng) | B17: =B15+B16 -> 1 | C17: =SUMPRODUCT(B15:B16,C15:C16) -> 282 | D17: =SUMPRODUCT($B15:$B16,D15:D16) -> 139500 | E17: =SUMPRODUCT($B15:$B16,E15:E16) -> 14699.66 | F17: =IFERROR((D17-E17)/D17,0) -> 0.89462609 | G17: =SUMPRODUCT($B15:$B16,G15:G16) -> 99000 | H17: =IFERROR((G17-E17)/G17,0) -> 0.85151859
A18: Kiểm tra: tổng tỷ trọng phải = 100% | B18: =IF(B17=0,"Chưa điền",IF(ABS(B17-1)<0.001,"Đạt","Sai: tổng khác 100%")) -> Đạt
A19: Kiểm tra: giá mỗi việc vượt hạn mức ≥ giá sàn mỗi việc (trang 1, dòng 26)? | B19: =IF(B11=0,"Chưa điền",IF(B11>='1_Chi phí mỗi việc'!B26,"Đạt","Thấp hơn giá sàn")) -> Đạt
A21: Tỷ trọng doanh thu đến từ khách dùng nhiều | B21: =IFERROR(B16*D16/D17,0) -> 0.39677419
A22: Trong đó: phí vượt hạn mức | B22: =IFERROR(B16*MAX(0,C16-B10)*B11/D17,0) -> 0.29032258
A23: Cảnh báo phụ thuộc | B23: =IF(D17=0,"Chưa điền",IF(B21>0.5,"Trên 50% doanh thu đến từ khách dùng nhiều: xem tình huống đặc biệt ở trang 5","Đạt")) -> Đạt
A25: PHÉP THỬ GIÁ: dùng chính quy tắc của Ngày 22 và chỉ số của Ngày 23
A26: Lương 1 tháng của người được thay | B26: 3000000 | C26: VND / tháng | D26: Đề bài 3
A27: Tỷ lệ chia doanh thu cho đối tác / kênh bán | B27: 0 | C27: % doanh thu | D27: Đề bài 3 (bán trực tiếp)
A28: Nhóm khách | B28: Trả mỗi tháng | C28: So với lương người được thay | D28: Quy tắc neo 50–70% lương (Ngày 22) | E28: Tiền AI ÷ doanh thu (chỉ số Ngày 23) | F28: Mức theo Ngày 23
A29: Khách thường | B29: =D15 -> 99000 | C29: =IFERROR(B29/$B$26,"") -> 0.033 | D29: =IF(C29="","",IF(C29<0.5,"Dưới 50%: còn dư địa",IF(C29<=0.7,"Trong vùng 50–70%","Trên 70%: khách thà thuê người? Xem dòng 34"))) -> Dưới 50%: còn dư địa | E29: =IFERROR(E15/B29,"") -> 0.06318358 | F29: =IF(E29="","",IF(E29<0.3,"Ổn (dưới 0,3)",IF(E29<=0.6,"Đáng lo (0,3–0,6)","Nguy (trên 0,6)"))) -> Ổn (dưới 0,3)
A30: Khách dùng nhiều, gói kết hợp | B30: =D16 -> 369000 | C30: =IFERROR(B30/$B$26,"") -> 0.123 | D30: =IF(C30="","",IF(C30<0.5,"Dưới 50%: còn dư địa",IF(C30<=0.7,"Trong vùng 50–70%","Trên 70%: khách thà thuê người? Xem dòng 34"))) -> Dưới 50%: còn dư địa | E30: =IFERROR(E16/B30,"") -> 0.16951692 | F30: =IF(E30="","",IF(E30<0.3,"Ổn (dưới 0,3)",IF(E30<=0.6,"Đáng lo (0,3–0,6)","Nguy (trên 0,6)"))) -> Ổn (dưới 0,3)
A31: Khách dùng nhiều, nếu bán gói không giới hạn | B31: =G16 -> 99000 | C31: =IFERROR(B31/$B$26,"") -> 0.033 | D31: =IF(C31="","",IF(C31<0.5,"Dưới 50%: còn dư địa",IF(C31<=0.7,"Trong vùng 50–70%","Trên 70%: khách thà thuê người? Xem dòng 34"))) -> Dưới 50%: còn dư địa | E31: =IFERROR(E16/B31,"") -> 0.6318358 | F31: =IF(E31="","",IF(E31<0.3,"Ổn (dưới 0,3)",IF(E31<=0.6,"Đáng lo (0,3–0,6)","Nguy (trên 0,6)"))) -> Nguy (trên 0,6)
A32: Biên lợi nhuận gộp bình quân sau khi chia cho đối tác | B32: =IFERROR((D17*(1-B27)-E17)/D17,"") -> 0.89462609 | C32: =IF(B32="","",IF(B32>0.5,"Ổn",IF(B32>=0.35,"Đáng lo","Nguy"))) -> Ổn | D32: Ngày 23: trên 50% ổn · 35–50% đáng lo · dưới 35% nguy
A33: Để sau: làm xong trang 5 thì quay lại so tỷ lệ chia ở dòng 27 với mức tối đa tự tính ở trang 5, dòng 77. Ngưỡng 50% của Ngày 23 chưa đủ: với bản mẫu, chia quá khoảng 14% là giá trị hiện tại ròng đã âm dù biên sau chia vẫn trên 50%.
A34: Khách dùng nhiều vượt 70% lương không phải lỗi bắt buộc sửa: KHÔNG hạ phí vượt xuống dưới giá sàn. Hỏi lại: với khối lượng đó, khách có phải thuê hơn 1 người không? Nếu vẫn vượt, đó là rủi ro khách bỏ đi (trang 5, dòng 68): ghi vào trang 7.
A35: CÁCH NHẬP DÒNG 9–12 THEO CÁCH TÍNH TIỀN ĐÃ CHỌN Ở DÒNG 6
A36: Theo lượt dùng | B36: Dòng 9 = 0 · dòng 10 = 0 · dòng 11 = giá mỗi việc
A37: Theo người dùng (tài khoản) | B37: Dòng 9 = giá mỗi tài khoản × số tài khoản của 1 khách · dòng 10 = mức dùng hợp lý · dòng 11 = phí vượt (không thu thì để trống, bỏ qua dòng 19, xem rủi ro ở dòng 31)
A38: Theo kết quả | B38: Dòng 9 = 0 · dòng 10 = 0 · dòng 11 = giá mỗi kết quả × tỷ lệ việc ra kết quả
A39: Kết hợp (bản mẫu) | B39: Dòng 9 = 499.000 · dòng 10 = 300 việc · dòng 11 = 1.500 đồng mỗi việc
A40: Dòng 12 | B40: Chỉ để so sánh: nhập bằng phí cố định dòng 9; nếu dòng 9 = 0 thì nhập mức trọn gói nhóm từng cân nhắc.

Sheet 3_Giả định
A1: 3 · Giả định cho 3 kịch bản
A2: Lạc quan = trình bày với nhà đầu tư · Cơ sở = lập kế hoạch · Xấu = để sống sót. Điền cột CƠ SỞ trước, có nguồn hoặc lý do. Cột Lạc quan, Xấu có sẵn mặc định theo Cơ sở (xem cột Gợi ý); sửa nếu có lý do.
A4: Giả định | B4: Lạc quan | C4: Cơ sở | D4: Xấu | E4: Đơn vị | F4: Nguồn / lý do | G4: Gợi ý · bản mẫu (Lạc quan / Cơ sở / Xấu)
A5: Hệ số doanh thu bình quân so với trang 2 (1 = giữ nguyên · 1,1 = cao hơn 10% · 0,8 = thấp hơn 20%) | B5: 1.1 | C5: 1 | D5: 0.8 | E5: × | F5: Cơ sở = 1. Lạc quan, xấu: mặc định 1,1 và 0,8; sửa nếu có lý do | G5: Bản mẫu: 1,1 / 1 / 0,8. Xấu: bị ép giảm giá; lạc quan: bán được gói cao hơn.
A6: Hệ số chi phí AI / khách so với trang 2 (gõ như dòng 5) | B6: 0.9 | C6: 1 | D6: 1.2 | E6: × | G6: Bản mẫu: 0,9 / 1 / 1,2. Giá gọi AI hoặc cách khách dùng thay đổi.
A7: Khách mới tháng 1 (số khách ký được trong tháng đầu bán) | B7: =C7*1.3 -> 390 | C7: 300 | D7: =C7*0.5 -> 150 | E7: khách | F7: Đề bài 3 | G7: Cơ sở: số khách đội bán hàng ký được thật trong tháng đầu. Mặc định: lạc quan = cơ sở × 1,3; xấu = cơ sở × 0,5. (Bản mẫu tự đặt 40 / 30 / 15.)
A8: Tăng trưởng khách mới / tháng (tính kép: 5%/tháng → tháng 24 gấp khoảng 3 lần tháng 1; 20%/tháng → gấp khoảng 66 lần) | B8: =C8*1.6 -> 0.128 | C8: 0.08 | D8: =C8*0.4 -> 0.032 | E8: % | F8: Đề bài 3 | G8: Mặc định: lạc quan × 1,6, xấu × 0,4. Bản mẫu: 8% / 5% / 2%. Trên 10% mỗi tháng cần lý do rất chắc.
A9: Tỷ lệ rời bỏ / tháng | B9: =C9*0.6 -> 0.09 | C9: 0.15 | D9: =C9*1.6 -> 0.24 | E9: % | F9: Đề bài 3: Người bán nhỏ, trả theo tháng, bỏ khi hết mùa | G9: Chưa có số đo: lấy từ phỏng vấn hoặc thử nghiệm, ghi "Giả định". Xấu phải ≥ 1,5 × cơ sở. Mặc định: lạc quan × 0,6, xấu × 1,6. Bản mẫu: 3% / 5% / 8%.
A10: Chi phí có một khách (CAC) = tiền quảng cáo và bán hàng 1 tháng ÷ số khách mới tháng đó | B10: =C10*0.8 -> 560000 | C10: 700000 | D10: =C10*1.5 -> 1050000 | E10: VND / khách | F10: Đề bài 3: Quảng cáo mạng xã hội | G10: Xấu phải ≥ 1,5 × cơ sở. Mặc định: lạc quan × 0,8, xấu × 1,5. (Bản mẫu tự đặt 1,2 / 1,5 / 2,3 triệu đồng.)
A11: Chi phí cố định / tháng (lương đội, văn phòng, hạ tầng trả cố định) | B11: =C11 -> 120000000 | C11: 120000000 | D11: =C11 -> 120000000 | E11: VND / tháng | F11: Đề bài 3: Đội 4 người và văn phòng | G11: Gõ đủ số đồng. Gồm lương đội phát triển (đã tách khỏi trang 1) và chi phí kiểm thử lại mỗi khi đổi mô hình hoặc câu lệnh. Bản mẫu: 150 triệu.
A12: Chi phí xây dựng ban đầu, gồm chi phí thử sai (chi một lần ở tháng 0) | B12: =C12 -> 400000000 | C12: 400000000 | D12: =C12 -> 400000000 | E12: VND | F12: Đề bài 3: Gồm chi phí thử sai 3 tháng (360tr) và token, kiểm thử (40tr) | G12: Gõ đủ số đồng. Gồm cả chi phí thử sai trước khi ra mắt: công đội, token chạy thử, chạy bộ câu hỏi kiểm thử sau mỗi lần sửa, tối ưu câu lệnh, làm dữ liệu mẫu, rà soát pháp lý. Bài toán càng khó càng nhiều vòng thử. Bản mẫu: 600 triệu (3 lập trình viên × 4 tháng + hạ tầng).
A13: Tiền mặt hoặc ngân sách đã duyệt (trước khi chi xây dựng) | B13: =C13 -> 1500000000 | C13: 1500000000 | D13: =C13 -> 1500000000 | E13: VND | F13: Đề bài 3 | G13: Gõ đủ số đồng. Dự án trong công ty: ghi ngân sách đã duyệt. Để trống thì mọi kịch bản hết tiền ngay tháng 1. Bản mẫu: 2 tỷ.
A14: Lãi suất chiết khấu / năm | B14: 0.15 | C14: 0.15 | D14: 0.15 | E14: % | F14: Giả định của lớp: chi phí vốn cho dự án rủi ro cao | G14: Giữ 15% nếu không có lý do khác.
A16: Giá trị tính ra
A17: Doanh thu bình quân / khách / tháng | B17: ='2_Định giá'!D17*B5*(1-'2_Định giá'!$B$27) -> 153450 | C17: ='2_Định giá'!D17*C5*(1-'2_Định giá'!$B$27) -> 139500 | D17: ='2_Định giá'!D17*D5*(1-'2_Định giá'!$B$27) -> 111600
A18: Chi phí AI (giá vốn) / khách / tháng | B18: ='2_Định giá'!E17*B6 -> 13229.694 | C18: ='2_Định giá'!E17*C6 -> 14699.66 | D18: ='2_Định giá'!E17*D6 -> 17639.592
A19: Doanh thu bình quân đã trừ phần chia cho đối tác (trang 2, dòng 27).
A20: Kiểm tra kịch bản xấu
A21: Tỷ lệ rời bỏ (xấu) ≥ 1,5 × cơ sở? | B21: =IF(C9=0,"Chưa điền",IF(D9>=1.5*C9,"Đạt","Chưa đủ sốc")) -> Đạt
A22: Chi phí có một khách (xấu) ≥ 1,5 × cơ sở? | B22: =IF(C10=0,"Chưa điền",IF(D10>=1.5*C10,"Đạt","Chưa đủ sốc")) -> Đạt

Sheet 4_Chỉ số mỗi khách
A1: 4 · Chỉ số trên mỗi khách: có lãi trên từng khách không?
A2: Giá trị vòng đời (LTV) tính trên lợi nhuận gộp, KHÔNG tính trên doanh thu.
A4: Chỉ số | B4: Lạc quan | C4: Cơ sở | D4: Xấu | E4: Ngưỡng tham khảo
A5: Doanh thu bình quân / khách / tháng | B5: ='3_Giả định'!B17 -> 153450 | C5: ='3_Giả định'!C17 -> 139500 | D5: ='3_Giả định'!D17 -> 111600
A6: Lợi nhuận gộp / khách / tháng | B6: ='3_Giả định'!B17-'3_Giả định'!B18 -> 140220.31 | C6: ='3_Giả định'!C17-'3_Giả định'!C18 -> 124800.34 | D6: ='3_Giả định'!D17-'3_Giả định'!D18 -> 93960.408
A7: Biên lợi nhuận gộp | B7: =IFERROR(B6/B5,0) -> 0.91378499 | C7: =IFERROR(C6/C5,0) -> 0.89462609 | D7: =IFERROR(D6/D5,0) -> 0.84193914 | E7: ≥ 60%
A8: Số tháng khách ở lại = 1 ÷ tỷ lệ rời bỏ | B8: =IFERROR(1/'3_Giả định'!B9,0) -> 11.111111 | C8: =IFERROR(1/'3_Giả định'!C9,0) -> 6.6666667 | D8: =IFERROR(1/'3_Giả định'!D9,0) -> 4.1666667
A9: Giá trị vòng đời (LTV) = lợi nhuận gộp × số tháng ở lại | B9: =B6*B8 -> 1558003.4 | C9: =C6*C8 -> 832002.27 | D9: =D6*D8 -> 391501.7
A10: Chi phí có một khách (CAC) | B10: ='3_Giả định'!B10 -> 560000 | C10: ='3_Giả định'!C10 -> 700000 | D10: ='3_Giả định'!D10 -> 1050000
A11: LTV ÷ CAC (lần) | B11: =IFERROR(B9/B10,0) -> 2.7821489 | C11: =IFERROR(C9/C10,0) -> 1.1885747 | D11: =IFERROR(D9/D10,0) -> 0.37285876 | E11: > 3 (Ngày 23); mô hình của bạn: trang 5, dòng 74
A12: Thời gian hoàn vốn chi phí có khách (tháng) | B12: =IFERROR(B10/B6,0) -> 3.9937154 | C12: =IFERROR(C10/C6,0) -> 5.6089591 | D12: =IFERROR(D10/D6,0) -> 11.17492 | E12: < 12 tháng
A13: Đánh giá | B13: =IF(B5<=0,"Chưa điền trang 2–3",IF(B6<=0,"Lỗ trên từng khách",IF(AND(B11>3,B12<12,B7>=0.6),"Khỏe",IF(B11>=1,"Cần cải thiện","Đốt tiền")))) -> Cần cải thiện | C13: =IF(C5<=0,"Chưa điền trang 2–3",IF(C6<=0,"Lỗ trên từng khách",IF(AND(C11>3,C12<12,C7>=0.6),"Khỏe",IF(C11>=1,"Cần cải thiện","Đốt tiền")))) -> Cần cải thiện | D13: =IF(D5<=0,"Chưa điền trang 2–3",IF(D6<=0,"Lỗ trên từng khách",IF(AND(D11>3,D12<12,D7>=0.6),"Khỏe",IF(D11>=1,"Cần cải thiện","Đốt tiền")))) -> Đốt tiền

Sheet 5_Dòng tiền & hiệu quả
A1: 5 · Dòng tiền 24 tháng và hiệu quả đầu tư (3 kịch bản)
A2: Trang này tự tính: chỉ đọc kết quả, trừ ô vàng B54 (mức làm xấu). Kết quả chỉ có nghĩa khi trang 1–3 đã điền đủ. Tháng 0 = chi phí xây dựng. Bảng độ nhạy ở dòng 53, mức cảnh báo tự tính ở dòng 70–77.
A4: Kịch bản / dòng | B4: Tháng 0 | C4: T1 | D4: T2 | E4: T3 | F4: T4 | G4: T5 | H4: T6 | I4: T7 | J4: T8 | K4: T9 | L4: T10 | M4: T11 | N4: T12 | O4: T13 | P4: T14 | Q4: T15 | R4: T16 | S4: T17 | T4: T18 | U4: T19 | V4: T20 | W4: T21 | X4: T22 | Y4: T23 | Z4: T24
A5: LẠC QUAN
A6: Khách mới | C6: ='3_Giả định'!$B$7*(1+'3_Giả định'!$B$8)^0 -> 390 | D6: ='3_Giả định'!$B$7*(1+'3_Giả định'!$B$8)^1 -> 439.92 | E6: ='3_Giả định'!$B$7*(1+'3_Giả định'!$B$8)^2 -> 496.22976 | F6: ='3_Giả định'!$B$7*(1+'3_Giả định'!$B$8)^3 -> 559.74717 | G6: ='3_Giả định'!$B$7*(1+'3_Giả định'!$B$8)^4 -> 631.39481 | H6: ='3_Giả định'!$B$7*(1+'3_Giả định'!$B$8)^5 -> 712.21334 | I6: ='3_Giả định'!$B$7*(1+'3_Giả định'!$B$8)^6 -> 803.37665 | J6: ='3_Giả định'!$B$7*(1+'3_Giả định'!$B$8)^7 -> 906.20886 | K6: ='3_Giả định'!$B$7*(1+'3_Giả định'!$B$8)^8 -> 1022.2036 | L6: ='3_Giả định'!$B$7*(1+'3_Giả định'!$B$8)^9 -> 1153.0457 | M6: ='3_Giả định'!$B$7*(1+'3_Giả định'!$B$8)^10 -> 1300.6355 | N6: ='3_Giả định'!$B$7*(1+'3_Giả định'!$B$8)^11 -> 1467.1168 | O6: ='3_Giả định'!$B$7*(1+'3_Giả định'!$B$8)^12 -> 1654.9078 | P6: ='3_Giả định'!$B$7*(1+'3_Giả định'!$B$8)^13 -> 1866.736 | Q6: ='3_Giả định'!$B$7*(1+'3_Giả định'!$B$8)^14 -> 2105.6782 | R6: ='3_Giả định'!$B$7*(1+'3_Giả định'!$B$8)^15 -> 2375.205 | S6: ='3_Giả định'!$B$7*(1+'3_Giả định'!$B$8)^16 -> 2679.2313 | T6: ='3_Giả định'!$B$7*(1+'3_Giả định'!$B$8)^17 -> 3022.1729 | U6: ='3_Giả định'!$B$7*(1+'3_Giả định'!$B$8)^18 -> 3409.011 | V6: ='3_Giả định'!$B$7*(1+'3_Giả định'!$B$8)^19 -> 3845.3644 | W6: ='3_Giả định'!$B$7*(1+'3_Giả định'!$B$8)^20 -> 4337.571 | X6: ='3_Giả định'!$B$7*(1+'3_Giả định'!$B$8)^21 -> 4892.7801 | Y6: ='3_Giả định'!$B$7*(1+'3_Giả định'!$B$8)^22 -> 5519.056 | Z6: ='3_Giả định'!$B$7*(1+'3_Giả định'!$B$8)^23 -> 6225.4951
A7: Khách đang dùng | B7: 0 | C7: =B7*(1-'3_Giả định'!$B$9)+C6 -> 390 | D7: =C7*(1-'3_Giả định'!$B$9)+D6 -> 794.82 | E7: =D7*(1-'3_Giả định'!$B$9)+E6 -> 1219.516 | F7: =E7*(1-'3_Giả định'!$B$9)+F6 -> 1669.5067 | G7: =F7*(1-'3_Giả định'!$B$9)+G6 -> 2150.6459 | H7: =G7*(1-'3_Giả định'!$B$9)+H6 -> 2669.3011 | I7: =H7*(1-'3_Giả định'!$B$9)+I6 -> 3232.4407 | J7: =I7*(1-'3_Giả định'!$B$9)+J6 -> 3847.7299 | ... Z7: =Y7*(1-'3_Giả định'!$B$9)+Z6 -> 32026.616
A8: Doanh thu | C8: =C7*'3_Giả định'!$B$17 -> 59845500 | D8: =D7*'3_Giả định'!$B$17 -> 121965129 | E8: =E7*'3_Giả định'!$B$17 -> 1.8713472e+08 | F8: =F7*'3_Giả định'!$B$17 -> 256185802 | G8: =G7*'3_Giả định'!$B$17 -> 330016613 | H8: =H7*'3_Giả định'!$B$17 -> 4.0960426e+08 | I8: =I7*'3_Giả định'!$B$17 -> 4.9601802e+08 | J8: =J7*'3_Giả định'!$B$17 -> 5.9043415e+08 | ... Z8: =Z7*'3_Giả định'!$B$17 -> 4914484201
A9: Chi phí AI (giá vốn) | C9: =C7*'3_Giả định'!$B$18 -> 5159580.6 | D9: =D7*'3_Giả định'!$B$18 -> 10515225 | E9: =E7*'3_Giả định'!$B$18 -> 16133823 | F9: =F7*'3_Giả định'!$B$18 -> 22087062 | G9: =G7*'3_Giả định'!$B$18 -> 28452387 | H9: =H7*'3_Giả định'!$B$18 -> 35314036 | I9: =I7*'3_Giả định'!$B$18 -> 42764200 | J9: =J7*'3_Giả định'!$B$18 -> 50904288 | ... Z9: =Z7*'3_Giả định'!$B$18 -> 4.2370232e+08
A10: Lợi nhuận gộp | C10: =C8-C9 -> 54685919 | D10: =D8-D9 -> 1.114499e+08 | E10: =E8-E9 -> 1.710009e+08 | F10: =F8-F9 -> 2.3409874e+08 | G10: =G8-G9 -> 3.0156423e+08 | H10: =H8-H9 -> 3.7429022e+08 | I10: =I8-I9 -> 4.5325382e+08 | J10: =J8-J9 -> 5.3952986e+08 | ... Z10: =Z8-Z9 -> 4490781879
A11: Chi phí bán hàng (chi phí có khách × khách mới) | C11: =C6*'3_Giả định'!$B$10 -> 218400000 | D11: =D6*'3_Giả định'!$B$10 -> 246355200 | E11: =E6*'3_Giả định'!$B$10 -> 2.7788867e+08 | F11: =F6*'3_Giả định'!$B$10 -> 3.1345841e+08 | G11: =G6*'3_Giả định'!$B$10 -> 3.5358109e+08 | H11: =H6*'3_Giả định'!$B$10 -> 3.9883947e+08 | I11: =I6*'3_Giả định'!$B$10 -> 449890924 | J11: =J6*'3_Giả định'!$B$10 -> 5.0747696e+08 | ... Z11: =Z6*'3_Giả định'!$B$10 -> 3486277282
A12: Chi phí cố định | C12: ='3_Giả định'!$B$11 -> 120000000 | D12: ='3_Giả định'!$B$11 -> 120000000 | E12: ='3_Giả định'!$B$11 -> 120000000 | F12: ='3_Giả định'!$B$11 -> 120000000 | G12: ='3_Giả định'!$B$11 -> 120000000 | H12: ='3_Giả định'!$B$11 -> 120000000 | I12: ='3_Giả định'!$B$11 -> 120000000 | J12: ='3_Giả định'!$B$11 -> 120000000 | ... Z12: ='3_Giả định'!$B$11 -> 120000000
A13: Dòng tiền ròng | B13: =-'3_Giả định'!$B$12 -> -400000000 | C13: =C10-C11-C12 -> -2.8371408e+08 | D13: =D10-D11-D12 -> -2.549053e+08 | E13: =E10-E11-E12 -> -2.2688776e+08 | F13: =F10-F11-F12 -> -1.9935968e+08 | G13: =G10-G11-G12 -> -1.7201687e+08 | H13: =H10-H11-H12 -> -144549253 | I13: =I10-I11-I12 -> -1.1663711e+08 | J13: =J10-J11-J12 -> -87947103 | ... Z13: =Z10-Z11-Z12 -> 8.845046e+08
A14: Tiền mặt cuối kỳ | B14: ='3_Giả định'!$B$13+B13 -> 1100000000 | C14: =B14+C13 -> 8.1628592e+08 | D14: =C14+D13 -> 5.6138062e+08 | E14: =D14+E13 -> 3.3449286e+08 | F14: =E14+F13 -> 1.3513318e+08 | G14: =F14+G13 -> -36883682 | H14: =G14+H13 -> -1.8143294e+08 | I14: =H14+I13 -> -2.9807004e+08 | J14: =I14+J13 -> -3.8601714e+08 | ... Z14: =Y14+Z13 -> 4525052086
A15: Dòng tiền lũy kế của dự án | B15: =B13 -> -400000000 | C15: =B15+C13 -> -6.8371408e+08 | D15: =C15+D13 -> -9.3861938e+08 | E15: =D15+E13 -> -1165507141 | F15: =E15+F13 -> -1364866816 | G15: =F15+G13 -> -1536883682 | H15: =G15+H13 -> -1681432935 | I15: =H15+I13 -> -1798070040 | J15: =I15+J13 -> -1886017144 | ... Z15: =Y15+Z13 -> 3025052086
A17: CƠ SỞ
A18: Khách mới | C18: ='3_Giả định'!$C$7*(1+'3_Giả định'!$C$8)^0 -> 300 | D18: ='3_Giả định'!$C$7*(1+'3_Giả định'!$C$8)^1 -> 324 | E18: ='3_Giả định'!$C$7*(1+'3_Giả định'!$C$8)^2 -> 349.92 | F18: ='3_Giả định'!$C$7*(1+'3_Giả định'!$C$8)^3 -> 377.9136 | G18: ='3_Giả định'!$C$7*(1+'3_Giả định'!$C$8)^4 -> 408.14669 | H18: ='3_Giả định'!$C$7*(1+'3_Giả định'!$C$8)^5 -> 440.79842 | I18: ='3_Giả định'!$C$7*(1+'3_Giả định'!$C$8)^6 -> 476.0623 | J18: ='3_Giả định'!$C$7*(1+'3_Giả định'!$C$8)^7 -> 514.14728 | K18: ='3_Giả định'!$C$7*(1+'3_Giả định'!$C$8)^8 -> 555.27906 | L18: ='3_Giả định'!$C$7*(1+'3_Giả định'!$C$8)^9 -> 599.70139 | M18: ='3_Giả định'!$C$7*(1+'3_Giả định'!$C$8)^10 -> 647.6775 | N18: ='3_Giả định'!$C$7*(1+'3_Giả định'!$C$8)^11 -> 699.4917 | O18: ='3_Giả định'!$C$7*(1+'3_Giả định'!$C$8)^12 -> 755.45104 | P18: ='3_Giả định'!$C$7*(1+'3_Giả định'!$C$8)^13 -> 815.88712 | Q18: ='3_Giả định'!$C$7*(1+'3_Giả định'!$C$8)^14 -> 881.15809 | R18: ='3_Giả định'!$C$7*(1+'3_Giả định'!$C$8)^15 -> 951.65073 | S18: ='3_Giả định'!$C$7*(1+'3_Giả định'!$C$8)^16 -> 1027.7828 | T18: ='3_Giả định'!$C$7*(1+'3_Giả định'!$C$8)^17 -> 1110.0054 | U18: ='3_Giả định'!$C$7*(1+'3_Giả định'!$C$8)^18 -> 1198.8058 | V18: ='3_Giả định'!$C$7*(1+'3_Giả định'!$C$8)^19 -> 1294.7103 | W18: ='3_Giả định'!$C$7*(1+'3_Giả định'!$C$8)^20 -> 1398.2871 | X18: ='3_Giả định'!$C$7*(1+'3_Giả định'!$C$8)^21 -> 1510.1501 | Y18: ='3_Giả định'!$C$7*(1+'3_Giả định'!$C$8)^22 -> 1630.9621 | Z18: ='3_Giả định'!$C$7*(1+'3_Giả định'!$C$8)^23 -> 1761.4391
A19: Khách đang dùng | B19: 0 | C19: =B19*(1-'3_Giả định'!$C$9)+C18 -> 300 | D19: =C19*(1-'3_Giả định'!$C$9)+D18 -> 579 | E19: =D19*(1-'3_Giả định'!$C$9)+E18 -> 842.07 | F19: =E19*(1-'3_Giả định'!$C$9)+F18 -> 1093.6731 | G19: =F19*(1-'3_Giả định'!$C$9)+G18 -> 1337.7688 | H19: =G19*(1-'3_Giả định'!$C$9)+H18 -> 1577.9019 | I19: =H19*(1-'3_Giả định'!$C$9)+I18 -> 1817.2789 | J19: =I19*(1-'3_Giả định'!$C$9)+J18 -> 2058.8344 | ... Z19: =Y19*(1-'3_Giả định'!$C$9)+Z18 -> 8244.7148
A20: Doanh thu | C20: =C19*'3_Giả định'!$C$17 -> 41850000 | D20: =D19*'3_Giả định'!$C$17 -> 80770500 | E20: =E19*'3_Giả định'!$C$17 -> 117468765 | F20: =F19*'3_Giả định'!$C$17 -> 1.525674e+08 | G20: =G19*'3_Giả định'!$C$17 -> 1.8661875e+08 | H20: =H19*'3_Giả định'!$C$17 -> 2.2011732e+08 | I20: =I19*'3_Giả định'!$C$17 -> 2.5351041e+08 | J20: =J19*'3_Giả định'!$C$17 -> 2.8720739e+08 | ... Z20: =Z19*'3_Giả định'!$C$17 -> 1150137716
A21: Chi phí AI (giá vốn) | C21: =C19*'3_Giả định'!$C$18 -> 4409898 | D21: =D19*'3_Giả định'!$C$18 -> 8511103 | E21: =E19*'3_Giả định'!$C$18 -> 12378143 | F21: =F19*'3_Giả định'!$C$18 -> 16076623 | G21: =G19*'3_Giả định'!$C$18 -> 19664747 | H21: =H19*'3_Giả định'!$C$18 -> 23194622 | I21: =I19*'3_Giả định'!$C$18 -> 26713382 | J21: =J19*'3_Giả định'!$C$18 -> 30264165 | ... Z21: =Z19*'3_Giả định'!$C$18 -> 1.211945e+08
A22: Lợi nhuận gộp | C22: =C20-C21 -> 37440102 | D22: =D20-D21 -> 72259397 | E22: =E20-E21 -> 1.0509062e+08 | F22: =F20-F21 -> 1.3649077e+08 | G22: =G20-G21 -> 1.66954e+08 | H22: =H20-H21 -> 1.969227e+08 | I22: =I20-I21 -> 2.2679703e+08 | J22: =J20-J21 -> 256943230 | ... Z22: =Z20-Z21 -> 1028943213
A23: Chi phí bán hàng (chi phí có khách × khách mới) | C23: =C18*'3_Giả định'!$C$10 -> 210000000 | D23: =D18*'3_Giả định'!$C$10 -> 226800000 | E23: =E18*'3_Giả định'!$C$10 -> 244944000 | F23: =F18*'3_Giả định'!$C$10 -> 264539520 | G23: =G18*'3_Giả định'!$C$10 -> 2.8570268e+08 | H23: =H18*'3_Giả định'!$C$10 -> 3.085589e+08 | I23: =I18*'3_Giả định'!$C$10 -> 3.3324361e+08 | J23: =J18*'3_Giả định'!$C$10 -> 3.599031e+08 | ... Z23: =Z18*'3_Giả định'!$C$10 -> 1233007366
A24: Chi phí cố định | C24: ='3_Giả định'!$C$11 -> 120000000 | D24: ='3_Giả định'!$C$11 -> 120000000 | E24: ='3_Giả định'!$C$11 -> 120000000 | F24: ='3_Giả định'!$C$11 -> 120000000 | G24: ='3_Giả định'!$C$11 -> 120000000 | H24: ='3_Giả định'!$C$11 -> 120000000 | I24: ='3_Giả định'!$C$11 -> 120000000 | J24: ='3_Giả định'!$C$11 -> 120000000 | ... Z24: ='3_Giả định'!$C$11 -> 120000000
A25: Dòng tiền ròng | B25: =-'3_Giả định'!$C$12 -> -400000000 | C25: =C22-C23-C24 -> -292559898 | D25: =D22-D23-D24 -> -274540603 | E25: =E22-E23-E24 -> -2.5985338e+08 | F25: =F22-F23-F24 -> -2.4804875e+08 | G25: =G22-G23-G24 -> -2.3874868e+08 | H25: =H22-H23-H24 -> -2.316362e+08 | I25: =I22-I23-I24 -> -2.2644658e+08 | J25: =J22-J23-J24 -> -2.2295987e+08 | ... Z25: =Z22-Z23-Z24 -> -324064153
A26: Tiền mặt cuối kỳ | B26: ='3_Giả định'!$C$13+B25 -> 1100000000 | C26: =B26+C25 -> 807440102 | D26: =C26+D25 -> 532899499 | E26: =D26+E25 -> 2.7304612e+08 | F26: =E26+F25 -> 24997376 | G26: =F26+G25 -> -2.137513e+08 | H26: =G26+H25 -> -4.453875e+08 | I26: =H26+I25 -> -6.7183408e+08 | J26: =I26+J25 -> -8.9479395e+08 | ... Z26: =Y26+Z25 -> -4966748318
A27: Dòng tiền lũy kế của dự án | B27: =B25 -> -400000000 | C27: =B27+C25 -> -692559898 | D27: =C27+D25 -> -967100501 | E27: =D27+E25 -> -1226953879 | F27: =E27+F25 -> -1475002624 | G27: =F27+G25 -> -1713751301 | H27: =G27+H25 -> -1945387501 | I27: =H27+I25 -> -2171834080 | J27: =I27+J25 -> -2394793946 | ... Z27: =Y27+Z25 -> -6466748318
A29: XẤU
A30: Khách mới | C30: ='3_Giả định'!$D$7*(1+'3_Giả định'!$D$8)^0 -> 150 | D30: ='3_Giả định'!$D$7*(1+'3_Giả định'!$D$8)^1 -> 154.8 | E30: ='3_Giả định'!$D$7*(1+'3_Giả định'!$D$8)^2 -> 159.7536 | F30: ='3_Giả định'!$D$7*(1+'3_Giả định'!$D$8)^3 -> 164.86572 | G30: ='3_Giả định'!$D$7*(1+'3_Giả định'!$D$8)^4 -> 170.14142 | H30: ='3_Giả định'!$D$7*(1+'3_Giả định'!$D$8)^5 -> 175.58594 | I30: ='3_Giả định'!$D$7*(1+'3_Giả định'!$D$8)^6 -> 181.20469 | J30: ='3_Giả định'!$D$7*(1+'3_Giả định'!$D$8)^7 -> 187.00324 | K30: ='3_Giả định'!$D$7*(1+'3_Giả định'!$D$8)^8 -> 192.98735 | L30: ='3_Giả định'!$D$7*(1+'3_Giả định'!$D$8)^9 -> 199.16294 | M30: ='3_Giả định'!$D$7*(1+'3_Giả định'!$D$8)^10 -> 205.53616 | N30: ='3_Giả định'!$D$7*(1+'3_Giả định'!$D$8)^11 -> 212.11331 | O30: ='3_Giả định'!$D$7*(1+'3_Giả định'!$D$8)^12 -> 218.90094 | P30: ='3_Giả định'!$D$7*(1+'3_Giả định'!$D$8)^13 -> 225.90577 | Q30: ='3_Giả định'!$D$7*(1+'3_Giả định'!$D$8)^14 -> 233.13475 | R30: ='3_Giả định'!$D$7*(1+'3_Giả định'!$D$8)^15 -> 240.59507 | S30: ='3_Giả định'!$D$7*(1+'3_Giả định'!$D$8)^16 -> 248.29411 | T30: ='3_Giả định'!$D$7*(1+'3_Giả định'!$D$8)^17 -> 256.23952 | U30: ='3_Giả định'!$D$7*(1+'3_Giả định'!$D$8)^18 -> 264.43919 | V30: ='3_Giả định'!$D$7*(1+'3_Giả định'!$D$8)^19 -> 272.90124 | W30: ='3_Giả định'!$D$7*(1+'3_Giả định'!$D$8)^20 -> 281.63408 | X30: ='3_Giả định'!$D$7*(1+'3_Giả định'!$D$8)^21 -> 290.64637 | Y30: ='3_Giả định'!$D$7*(1+'3_Giả định'!$D$8)^22 -> 299.94705 | Z30: ='3_Giả định'!$D$7*(1+'3_Giả định'!$D$8)^23 -> 309.54536
A31: Khách đang dùng | B31: 0 | C31: =B31*(1-'3_Giả định'!$D$9)+C30 -> 150 | D31: =C31*(1-'3_Giả định'!$D$9)+D30 -> 268.8 | E31: =D31*(1-'3_Giả định'!$D$9)+E30 -> 364.0416 | F31: =E31*(1-'3_Giả định'!$D$9)+F30 -> 441.53733 | G31: =F31*(1-'3_Giả định'!$D$9)+G30 -> 505.70979 | H31: =G31*(1-'3_Giả định'!$D$9)+H30 -> 559.92538 | I31: =H31*(1-'3_Giả định'!$D$9)+I30 -> 606.74799 | J31: =I31*(1-'3_Giả định'!$D$9)+J30 -> 648.13171 | ... Z31: =Y31*(1-'3_Giả định'!$D$9)+Z30 -> 1173.6911
A32: Doanh thu | C32: =C31*'3_Giả định'!$D$17 -> 16740000 | D32: =D31*'3_Giả định'!$D$17 -> 29998080 | E32: =E31*'3_Giả định'!$D$17 -> 40627043 | F32: =F31*'3_Giả định'!$D$17 -> 49275566 | G32: =G31*'3_Giả định'!$D$17 -> 56437213 | H32: =H31*'3_Giả định'!$D$17 -> 62487673 | I32: =I31*'3_Giả định'!$D$17 -> 67713075 | J32: =J31*'3_Giả định'!$D$17 -> 72331499 | ... Z32: =Z31*'3_Giả định'!$D$17 -> 1.3098393e+08
A33: Chi phí AI (giá vốn) | C33: =C31*'3_Giả định'!$D$18 -> 2645938.8 | D33: =D31*'3_Giả định'!$D$18 -> 4741522.3 | E33: =E31*'3_Giả định'!$D$18 -> 6421545.2 | F33: =F31*'3_Giả định'!$D$18 -> 7788538.3 | G33: =G31*'3_Giả định'!$D$18 -> 8920514.3 | H33: =H31*'3_Giả định'!$D$18 -> 9876855.2 | I33: =I31*'3_Giả định'!$D$18 -> 10702787 | J33: =J31*'3_Giả định'!$D$18 -> 11432779 | ... Z33: =Z31*'3_Giả định'!$D$18 -> 20703432
A34: Lợi nhuận gộp | C34: =C32-C33 -> 14094061 | D34: =D32-D33 -> 25256558 | E34: =E32-E33 -> 34205497 | F34: =F32-F33 -> 41487028 | G34: =G32-G33 -> 47516698 | H34: =H32-H33 -> 52610818 | I34: =I32-I33 -> 57010288 | J34: =J32-J33 -> 60898720 | ... Z34: =Z32-Z33 -> 1.1028049e+08
A35: Chi phí bán hàng (chi phí có khách × khách mới) | C35: =C30*'3_Giả định'!$D$10 -> 157500000 | D35: =D30*'3_Giả định'!$D$10 -> 162540000 | E35: =E30*'3_Giả định'!$D$10 -> 167741280 | F35: =F30*'3_Giả định'!$D$10 -> 173109001 | G35: =G30*'3_Giả định'!$D$10 -> 178648489 | H35: =H30*'3_Giả định'!$D$10 -> 1.8436524e+08 | I35: =I30*'3_Giả định'!$D$10 -> 1.9026493e+08 | J35: =J30*'3_Giả định'!$D$10 -> 196353406 | ... Z35: =Z30*'3_Giả định'!$D$10 -> 3.2502263e+08
A36: Chi phí cố định | C36: ='3_Giả định'!$D$11 -> 120000000 | D36: ='3_Giả định'!$D$11 -> 120000000 | E36: ='3_Giả định'!$D$11 -> 120000000 | F36: ='3_Giả định'!$D$11 -> 120000000 | G36: ='3_Giả định'!$D$11 -> 120000000 | H36: ='3_Giả định'!$D$11 -> 120000000 | I36: ='3_Giả định'!$D$11 -> 120000000 | J36: ='3_Giả định'!$D$11 -> 120000000 | ... Z36: ='3_Giả định'!$D$11 -> 120000000
A37: Dòng tiền ròng | B37: =-'3_Giả định'!$D$12 -> -400000000 | C37: =C34-C35-C36 -> -2.6340594e+08 | D37: =D34-D35-D36 -> -2.5728344e+08 | E37: =E34-E35-E36 -> -2.5353578e+08 | F37: =F34-F35-F36 -> -2.5162197e+08 | G37: =G34-G35-G36 -> -2.5113179e+08 | H37: =H34-H35-H36 -> -251754423 | I37: =I34-I35-I36 -> -253254640 | J37: =J34-J35-J36 -> -2.5545469e+08 | ... Z37: =Z34-Z35-Z36 -> -3.3474213e+08
A38: Tiền mặt cuối kỳ | B38: ='3_Giả định'!$D$13+B37 -> 1100000000 | C38: =B38+C37 -> 8.3659406e+08 | D38: =C38+D37 -> 579310619 | E38: =D38+E37 -> 3.2577484e+08 | F38: =E38+F37 -> 74152863 | G38: =F38+G37 -> -1.7697893e+08 | H38: =G38+H37 -> -4.2873335e+08 | I38: =H38+I37 -> -6.8198799e+08 | J38: =I38+J37 -> -9.3744268e+08 | ... Z38: =Y38+Z37 -> -5616192515
A39: Dòng tiền lũy kế của dự án | B39: =B37 -> -400000000 | C39: =B39+C37 -> -6.6340594e+08 | D39: =C39+D37 -> -920689381 | E39: =D39+E37 -> -1174225164 | F39: =E39+F37 -> -1425847137 | G39: =F39+G37 -> -1676978928 | H39: =G39+H37 -> -1928733351 | I39: =H39+I37 -> -2181987991 | J39: =I39+J37 -> -2437442676 | ... Z39: =Y39+Z37 -> -7116192515
A42: TÓM TẮT HIỆU QUẢ ĐẦU TƯ
A43: Chỉ số | B43: Lạc quan | C43: Cơ sở | D43: Xấu | E43: Ngưỡng tham khảo
A44: Giá trị hiện tại ròng 24 tháng (đồng; lớn hơn 0 là đáng làm) | B44: {=B13+NPV('3_Giả định'!$B$14/12,C13:Z13)} -> 1981126391 | C44: {=B25+NPV('3_Giả định'!$C$14/12,C25:Z25)} -> -5591201777 | D44: {=B37+NPV('3_Giả định'!$D$14/12,C37:Z37)} -> -6128196562 | E44: > 0
A45: Tỷ suất hoàn vốn nội bộ (IRR, quy ra năm) | B45: =IFERROR((1+IRR(B13:Z13,0.01))^12-1,"Không tính được") -> 0.91234283 | C45: =IFERROR((1+IRR(B25:Z25,0.01))^12-1,"Không tính được") -> Không tính được | D45: =IFERROR((1+IRR(B37:Z37,0.01))^12-1,"Không tính được") -> Không tính được | E45: > chi phí vốn | F45: Lãi suất làm giá trị hiện tại ròng bằng 0; so với chi phí vốn 15%. Số rất lớn ở kịch bản lạc quan là do vốn quay về nhanh — chỉ dùng để so sánh, không đọc như lợi nhuận.
...

Sheet 6_Hiệu quả nội bộ
A1: 6 · Hiệu quả dự án AI dùng trong nội bộ (khi sản phẩm phục vụ chính công ty)
A2: Hiệu quả = (giá trị tạo ra − chi phí vận hành) so với chi phí đầu tư một lần. Không dùng thay cho trang 3–5 nếu sản phẩm bán ra thị trường.
A3: Lưu ý: giờ tiết kiệm chỉ thành tiền khi được dùng vào việc khác hoặc giúp giảm tuyển mới. Nếu không, chỉ ghi phần đo được ở dòng 9 và nói rõ lý do.
A4: Giả định | B4: Lạc quan | C4: Cơ sở | D4: Xấu | E4: Đơn vị | F4: Nguồn / lý do | G4: Gợi ý · bản mẫu (Lạc quan / Cơ sở / Xấu)
A5: Số nhân sự dùng công cụ | E5: người | G5: Số người sẽ dùng công cụ. Bản mẫu: 30 (1 phòng ban).
A6: Giờ tiết kiệm / người / tuần (chỉ tính giờ được dùng vào việc khác hoặc giúp giảm tuyển) | E6: giờ | G6: Chỉ tính giờ được dùng vào việc khác hoặc giúp giảm tuyển. Đo bằng thử nghiệm. Bản mẫu: 5 / 3 / 1,5.
A7: Tỷ lệ người dùng thật | E7: % | G7: Người dùng đều đặn ÷ tổng số người. Bản mẫu: 80% / 60% / 35%.
A8: Chi phí 1 giờ công (gồm phúc lợi) | E8: VND / giờ | G8: Lương + bảo hiểm + phúc lợi ÷ số giờ làm. Bản mẫu: 120.000.
A9: Giá trị khác / tháng (doanh thu tăng, giảm lỗi…) | E9: VND / tháng | G9: Chỉ đưa vào nếu đo được. Bản mẫu: 10 / 5 / 0 triệu.
A10: Chi phí xây dựng một lần | E10: VND (một lần) | G10: Bản mẫu: 400 / 400 / 500 triệu.
A11: Chi phí thay đổi quy trình & đào tạo (một lần) | E11: VND (một lần) | G11: Khoản hay bị quên. Bản mẫu: 50 / 60 / 80 triệu.
A12: Chi phí vận hành / tháng (API, hạ tầng, bảo trì) | E12: VND / tháng | G12: Gọi AI + hạ tầng + bảo trì. Bản mẫu: 15 / 18 / 25 triệu.
A13: Lãi suất chiết khấu / năm | B13: 0.15 | C13: 0.15 | D13: 0.15 | E13: % | F13: Giả định của lớp: chi phí vốn
A15: Kết quả | B15: Lạc quan | C15: Cơ sở | D15: Xấu | E15: Ngưỡng tham khảo
A16: Giá trị tạo ra / tháng | B16: =B5*B6*52/12*B7*B8+B9 -> 0 | C16: =C5*C6*52/12*C7*C8+C9 -> 0 | D16: =D5*D6*52/12*D7*D8+D9 -> 0
A17: Lợi ích ròng / tháng | B17: =B16-B12 -> 0 | C17: =C16-C12 -> 0 | D17: =D16-D12 -> 0 | E17: > 0
A18: Đầu tư một lần | B18: =B10+B11 -> 0 | C18: =C10+C11 -> 0 | D18: =D10+D11 -> 0
A19: Thời gian hoàn vốn | B19: =IF(B5=0,"Chưa điền",IF(B17>0,B18/B17,"Không hoàn vốn")) -> Chưa điền | C19: =IF(C5=0,"Chưa điền",IF(C17>0,C18/C17,"Không hoàn vốn")) -> Chưa điền | D19: =IF(D5=0,"Chưa điền",IF(D17>0,D18/D17,"Không hoàn vốn")) -> Chưa điền | E19: < 12 tháng
A20: Hiệu quả đầu tư sau 12 tháng (ROI) | B20: =IFERROR((12*B17-B18)/B18,0) -> 0 | C20: =IFERROR((12*C17-C18)/C18,0) -> 0 | D20: =IFERROR((12*D17-D18)/D18,0) -> 0 | E20: > 0
A21: Giá trị hiện tại ròng 24 tháng | B21: =PV(B13/12,24,-B17)-B18 -> 0 | C21: =PV(C13/12,24,-C17)-C18 -> 0 | D21: =PV(D13/12,24,-D17)-D18 -> 0 | E21: > 0
A22: Đánh giá nhanh | B22: =IF(B5=0,"Chưa điền",IF(NOT(ISNUMBER(B19)),"Dừng",IF(B19<12,"Làm","Thử nghiệm nhỏ"))) -> Chưa điền | C22: =IF(C5=0,"Chưa điền",IF(NOT(ISNUMBER(C19)),"Dừng",IF(C19<12,"Làm","Thử nghiệm nhỏ"))) -> Chưa điền | D22: =IF(D5=0,"Chưa điền",IF(NOT(ISNUMBER(D19)),"Dừng",IF(D19<12,"Làm","Thử nghiệm nhỏ"))) -> Chưa điền | E22: Hoàn vốn dưới 12 tháng: Làm · hoàn vốn được nhưng chậm: thử ở 1 phòng ban để đo tỷ lệ người dùng thật · không hoàn vốn: Dừng

Sheet 7_Quyết định
A1: 7 · Tự kiểm tra và ghi chú quyết định
A2: Các dòng tự kiểm tra tự tính. "Xem lại" hay "Cần kế hoạch cắt giảm" là câu hỏi để soát, không bắt buộc thành "Đạt": sửa nếu nhập sai; nếu số đúng thì giữ nguyên và giải thích trong ghi chú. Không chỉnh giả định chỉ để đẹp số.
A4: Điểm kiểm tra | B4: Kết quả (cơ sở) | C4: Đạt?
A5: Phần chìm ≥ 30% chi phí gọi AI | B5: ='1_Chi phí mỗi việc'!B25 -> 4.9280953 | C5: =IF(B5>=0.3,"Đạt","Xem lại") -> Đạt
A6: Biên lợi nhuận gộp bình quân ≥ 60% (gói kết hợp) | B6: ='4_Chỉ số mỗi khách'!C7 -> 0.89462609 | C6: =IF(B6>=0.6,"Đạt","Xem lại") -> Đạt
A7: LTV ÷ CAC > 3 (cơ sở) | B7: ='4_Chỉ số mỗi khách'!C11 -> 1.1885747 | C7: =IF(B7>3,"Đạt","Xem lại") -> Xem lại
A8: Hoàn vốn chi phí có khách < 12 tháng (cơ sở) | B8: ='4_Chỉ số mỗi khách'!C12 -> 5.6089591 | C8: =IF(AND(B8>0,B8<12),"Đạt","Xem lại") -> Đạt
A9: Kịch bản xấu: rời bỏ và chi phí có khách đủ sốc (≥ 1,5 lần) | B9: =IF(AND('3_Giả định'!C9>0,'3_Giả định'!C10>0,'3_Giả định'!D9>=1.5*'3_Giả định'!C9,'3_Giả định'!D10>=1.5*'3_Giả định'!C10),"Có","Không") -> Có | C9: =IF(B9="Có","Đạt","Xem lại") -> Đạt
A10: Kịch bản xấu: tháng hết tiền | B10: ='5_Dòng tiền & hiệu quả'!D47 -> 5 | C10: =IF(B10="Chưa điền","Chưa điền",IF(ISNUMBER(B10),IF(B10>=12,"Đạt","Cần kế hoạch cắt giảm"),"Đạt")) -> Cần kế hoạch cắt giảm
A11: Giá trị hiện tại ròng 24 tháng (cơ sở) | B11: ='5_Dòng tiền & hiệu quả'!C44 -> -5591201777 | C11: =IF(B11>0,"Đạt","Xem lại") -> Xem lại
A12: Biến nguy hiểm nhất (bảng độ nhạy, trang 5) | B12: ='5_Dòng tiền & hiệu quả'!B66 -> Chi phí có một khách tăng | C12: =IF(B12="Chưa đủ số liệu","Xem lại","Ghi vào câu 3") -> Ghi vào câu 3
A13: GHI CHÚ QUYẾT ĐỊNH: 5 câu, mỗi câu 1–3 câu văn, cả phần khoảng 200 chữ. Nhóm viết vào ô vàng dưới mỗi câu hỏi.
A14: 1. Quyết định: Làm (cả kịch bản cơ sở và xấu đều chịu được) / Thử nghiệm nhỏ (cơ sở tốt, xấu rủi ro: ghi quy mô, thời hạn) / Dừng (lỗ trên từng khách hoặc không hoàn vốn)? Vì sao? Nếu kịch bản xấu hết tiền trước tháng 12: ghi luôn kế hoạch cắt giảm.
A17: 2. Giá bán và cách tính tiền đã chọn — vì sao khách chấp nhận mức đó?
A20: 3. Biến số nguy hiểm nhất (theo bảng độ nhạy ở trang 5) và cách theo dõi.
A23: 4. Luật xử lý theo khuôn Ngày 23: NẾU [chỉ số vượt mức nào] TRONG [bao lâu, trên bao nhiêu khách] THÌ [việc cụ thể, bắt đầu bằng động từ] KHÔNG THÌ [việc cấm làm, để chặn phản xạ sai; không phải nhánh "ngược lại"]. Ví dụ: NẾU doanh thu bình quân dưới mức ở trang 5, dòng 72, TRONG 2 tháng liên tiếp trên ít nhất 20 khách, THÌ dừng mở rộng, thiết kế lại gói giá. KHÔNG THÌ không giảm giá gói cơ bản để kéo khách.
A26: 5. Mức cảnh báo tự tính (trang 5, dòng 72–77) đã điền vào bảng theo dõi Ngày 23 thế nào? Chưa có bảng Ngày 23: chép các mức đó, ghi mức nào là "nguy", mức nào "đáng lo", và ai theo dõi hằng tuần.

Sheet 8_Thang điểm
A1: 8 · Thang điểm (100 điểm)
A2: Trừ điểm: số bịa không có nguồn, chỉ 1 kịch bản, nhầm doanh thu với lợi nhuận.
A4: Tiêu chí | B4: Điểm | C4: Bài đạt khi | D4: Điểm (giảng viên chấm, nhóm không điền)
A5: Bài tập tài chính căn bản | B5: 10 | C5: Ba báo cáo đúng và khớp: bảng cân đối cân, tiền cuối kỳ khớp, trả lời đúng câu 1–3
A6: Chi phí mỗi việc đầy đủ | B6: 15 | C6: ≥ 4 nhóm chi phí; chỉ gồm chi phí phục vụ (không lẫn R&D, bán hàng); có tên mô hình và ngày tra giá
A7: Giá sống được trong mô hình | B7: 15 | C7: Giá lấy từ bài Ngày 22 và qua ba phép thử: neo lương 50–70%, tiền AI của khách dùng nhiều, biên sau chia đối tác
A8: Chỉ số trên mỗi khách | B8: 20 | C8: Công thức đúng; LTV tính trên lợi nhuận gộp; tỷ lệ rời bỏ và chi phí có khách có nguồn hoặc lý do rõ
A9: 3 kịch bản và độ nhạy | B9: 20 | C9: Kịch bản xấu là cú sốc thật; đọc bảng độ nhạy và chỉ ra biến số nguy hiểm nhất
A10: Ghi chú quyết định và mức cảnh báo | B10: 20 | C10: Quyết định rõ, bảo vệ bằng số; luật xử lý theo khuôn Ngày 23; mức cảnh báo tự tính đưa vào bảng Ngày 23
A11: TỔNG | B11: =SUM(B5:B10) -> 100 | D11: =SUM(D5:D10) -> 0
A12: Điểm thưởng: dùng số thật từ buổi trước (trang 0) | B12: tối đa 10 | C12: 2 điểm/đầu vào đã có và thật sự được dùng; tổng điểm không quá 100
A15: THANG ĐIỂM TRÌNH BÀY (1–5 điểm mỗi tiêu chí)
A16: Tiêu chí | B16: Mức 1 | C16: Mức 3 | D16: Mức 5
A17: Rõ ràng | B17: Câu đầu chưa có quyết định; người nghe phải đoán nhóm đề xuất gì | C17: Có quyết định nhưng nói sau phần mở đầu, hoặc thiếu giá bán | D17: Câu đầu tiên có quyết định, giá bán và 1 lý do
A18: Bằng chứng | B18: Con số không có nguồn, hoặc chỉ có kịch bản cơ sở | C18: Có số chính và nguồn, nhưng thiếu kịch bản xấu hoặc biến nguy hiểm nhất | D18: Đủ chi phí mỗi việc, biên lợi nhuận, LTV ÷ CAC, kịch bản xấu; số nào cũng có nguồn hoặc lý do
A19: Trả lời phản biện | B19: Né câu hỏi hoặc trả lời chung chung | C19: Trả lời đúng ý nhưng không dẫn số | D19: Trả lời thẳng, dẫn đúng con số trong file
A20: Đúng giờ | B20: Quá 4 phút | C20: Từ 3 đến 4 phút | D20: Không quá 3 phút
A22: Mức 2 và 4 dùng khi bài nằm giữa hai mô tả. Điểm buổi = 60% sản phẩm + 40% trình bày (60% giảng viên + 40% các nhóm khác chấm, không tự chấm nhóm mình).

Sheet 9_Số tham khảo
A1: 9 · Số tham khảo đã kiểm chứng (tra ngày 04/10/2026)
A2: Giá thay đổi thường xuyên: trước khi dùng, mở lại đường dẫn và ghi ngày tra của nhóm. Số nào không có trong bảng, nhóm tự tìm nguồn hoặc ghi lý do.
A4: Mô hình AI | B4: Đầu vào (USD / 1 triệu token) | C4: Đầu ra (USD / 1 triệu token) | D4: Nguồn chính thức | E4: Ghi chú
A5: OpenAI GPT-6 Luna | B5: 0.1 | C5: 0.5 | D5: https://developers.openai.com/api/docs/pricing | E5: Mức Standard, ngữ cảnh ngắn
A6: OpenAI GPT-6 Sol | B6: 2 | C6: 10 | D6: https://openai.com/index/introducing-gpt-6-sol-and-luna/ | E6: Mức Standard
A7: Anthropic Claude Haiku 4.5 | B7: 1 | C7: 5 | D7: https://platform.claude.com/docs/en/models/haiku-4-5/overview
A8: Anthropic Claude Sonnet 5.5 | B8: 2 | C8: 10 | D8: https://platform.claude.com/docs/en/models/haiku-4-5/overview | E8: Bảng so sánh trên cùng trang
A11: Số liệu Việt Nam | B11: Giá trị | C11: Đơn vị | D11: Nguồn | E11: Ghi chú
A12: Tỷ giá USD bán ra Vietcombank | B12: 26170 | C12: VND / USD | D12: https://thanhnien.vn/gia-usd-hom-nay-4102026-bien-dong-nhe-trong-tuan-khi-euro-bang-anh-tiep-tuc-giam-185261003210750485.htm | E12: Báo chí đưa tin sáng 04/10/2026; đối chiếu trang Vietcombank khi dùng
A13: Tỷ giá trung tâm Ngân hàng Nhà nước | B13: 25636 | C13: VND / USD | D13: https://qdnd.vn/kinh-te/tin-tuc/ty-gia-usd-hom-nay-4-10-dong-usd-tang-tuan-thu-ba-lien-tiep-1059250 | E13: Báo QĐND đưa tin ngày 04/10/2026
A14: Lương tối thiểu tháng, vùng I (Hà Nội, TP.HCM) | B14: 5310000 | C14: VND / tháng | D14: https://xaydungchinhsach.chinhphu.vn/tu-1-1-2026-muc-luong-toi-thieu-duoc-tang-bao-nhieu-119251111091442629.htm | E14: Nghị định 293/2025/NĐ-CP, hiệu lực 01/01/2026
A15: Lương tối thiểu giờ, vùng I | B15: 25500 | C15: VND / giờ | D15: https://xaydungchinhsach.chinhphu.vn/tu-1-1-2026-muc-luong-toi-thieu-duoc-tang-bao-nhieu-119251111091442629.htm | E15: Nghị định 293/2025/NĐ-CP; là mức sàn, chưa gồm bảo hiểm
A18: Số KHÔNG có trong bảng | B18: Cách xử lý
A19: Tỷ lệ rời bỏ, chi phí có một khách của SME Việt Nam | B19: Lớp chưa kiểm chứng được nguồn công khai đáng tin. Dùng số từ phỏng vấn hoặc thử nghiệm; nếu không có, ghi dải giả định và lý do. Không ghi "theo số chuẩn ngành" khi không chỉ ra được nguồn. Nếu có dải: số giữa vào cột Cơ sở, hai đầu dải vào Lạc quan và Xấu.
A20: LTV ÷ CAC > 3, hoàn vốn chi phí có khách < 12 tháng | B20: Ngưỡng tham khảo phổ biến trong ngành phần mềm thuê bao; lớp chưa kiểm chứng nguồn sơ cấp. Dùng để đọc kết quả, không phải luật.
A21: Giá sàn gấp 3 lần chi phí mỗi việc; phần chìm ≥ 30% chi phí gọi AI | B21: Kinh nghiệm của giảng viên, không phải chuẩn ngành.
A23: Ngưỡng nghe ở Ngày 22–23 | B23: Cách dùng hôm nay
A24: Biên lợi nhuận gộp ≥ 60%, dưới 50% là nguy (Ngày 22, slide 8) | B24: Diễn giả nêu, không kèm nguồn. Ngày 23 (slide 34) dẫn số thực đo của công ty AI chỉ 45–53% — chưa kiểm chứng. Dùng mức tối thiểu tự tính ở trang 5.
A25: Neo giá ở 50–70% lương người được thay (Ngày 22, slide 9) | B25: Kinh nghiệm diễn giả. Dùng làm phép thử ở trang 2, không phải luật.
A26: Ranh giới bán tự phục vụ dưới 50 USD, bán trực tiếp trên 1.000 USD mỗi tháng (Ngày 22, slide 17–18) | B26: Ngưỡng của thị trường Mỹ. Ranh giới của nhóm là chi phí có một khách tối đa tự tính ở trang 5.
A27: GitHub Copilot thu 10 USD, chi 80 USD, lỗ 70 USD mỗi người (Ngày 22, slide 3) | B27: WSJ 10/2023 đưa tin lỗ trung bình khoảng 20 USD/người/tháng; 80 USD là mức của một số người dùng nặng. Theo bản tóm tắt của AI Business, chưa đọc bài gốc WSJ.
A28: Nhãn nguồn [NGÀNH] · [TỰ TÍNH] · [TỰ ĐO] (Ngày 23, slide 11) | B28: Dùng ba nhãn này trong cột "Nguồn / lý do". Số chưa có nguồn, chưa đo: ghi "Giả định: … vì …", không gắn [NGÀNH].
